  0%|          | 0/601 [00:00<?, ?it/s]  0%|          | 0/601 [00:00<?, ?it/s]
multiprocessing.pool.RemoteTraceback: 
"""
Traceback (most recent call last):
  File "/u/sjl/miniconda3/envs/pyeuclid/lib/python3.10/multiprocessing/pool.py", line 125, in worker
    result = (True, func(*args, **kwds))
  File "/h/346/sjl/PyEuclid/test_intergps_dataset.py", line 63, in run_with_timeout
    p.start()
  File "/u/sjl/miniconda3/envs/pyeuclid/lib/python3.10/multiprocessing/process.py", line 118, in start
    assert not _current_process._config.get('daemon'), \
AssertionError: daemonic processes are not allowed to have children
"""

The above exception was the direct cause of the following exception:

Traceback (most recent call last):
  File "/h/346/sjl/PyEuclid/test_intergps_dataset.py", line 100, in <module>
    main()
  File "/h/346/sjl/PyEuclid/test_intergps_dataset.py", line 79, in main
    for result in tqdm(pool.imap_unordered(run_with_timeout, indices), total=len(indices)):
  File "/u/sjl/miniconda3/envs/pyeuclid/lib/python3.10/site-packages/tqdm/std.py", line 1181, in __iter__
    for obj in iterable:
  File "/u/sjl/miniconda3/envs/pyeuclid/lib/python3.10/multiprocessing/pool.py", line 873, in next
    raise value
AssertionError: daemonic processes are not allowed to have children
